<?xml version="1.0" encoding="utf-8"?>
<!-- =================================================================================== -->
<!-- |    This document was autogenerated by xacro from ./urdf/robot_arm.xacro         | -->
<!-- |    EDITING THIS FILE BY HAND IS NOT RECOMMENDED                                 | -->
<!-- =================================================================================== -->
<robot name="exploratoryHand">
  <!-- ros_control plugin -->
  <gazebo>
    <plugin filename="libgazebo_ros_control.so" name="gazebo_ros_control">
      <robotNamespace>/robot</robotNamespace>
      <robotSimType>gazebo_ros_control/DefaultRobotHWSim</robotSimType>
    </plugin>
  </gazebo>
  <!-- Link1 -->
  <gazebo reference="mobilefinger_1">
    <mu1>0.2</mu1>
    <mu2>0.2</mu2>
    <material>Gazebo/Orange</material>
  </gazebo>
  <!-- measured from model -->
  <!--property name="shoulder_height" value="0.089159" /-->
  <!--property name="shoulder_offset" value="0.13585" /-->
  <!-- shoulder_offset - elbow_offset + wrist_1_length = 0.10915 -->
  <!--property name="upper_arm_length" value="0.42500" /-->
  <!--property name="elbow_offset" value="0.1197" /-->
  <!-- CAD measured -->
  <!--property name="forearm_length" value="0.39225" /-->
  <!--property name="wrist_1_length" value="0.093" /-->
  <!-- CAD measured -->
  <!--property name="wrist_2_length" value="0.09465" /-->
  <!-- In CAD this distance is 0.930, but in the spec it is 0.09465 -->
  <!--property name="wrist_3_length" value="0.0823" /-->
  <!-- manually measured -->
  <link name="base_link">
    <visual>
      <geometry>
        <mesh filename="../meshes/ur5/visual/base.dae"/>
      </geometry>
      <material name="LightGrey">
        <color rgba="0.7 0.7 0.7 1.0"/>
      </material>
    </visual>
    <collision>
      <geometry>
        <mesh filename="../meshes/ur5/collision/base.stl"/>
      </geometry>
    </collision>
    <inertial>
      <mass value="4.0"/>
      <origin rpy="0 0 0" xyz="0.0 0.0 0.0"/>
      <inertia ixx="0.00443333156" ixy="0.0" ixz="0.0" iyy="0.00443333156" iyz="0.0" izz="0.0072"/>
    </inertial>
  </link>
  <joint name="shoulder_pan_joint" type="revolute">
    <parent link="base_link"/>
    <child link="shoulder_link"/>
    <origin rpy="0.0 0.0 0.0" xyz="0.0 0.0 0.089159"/>
    <axis xyz="0 0 1"/>
    <limit effort="150.0" lower="-3.14159265359" upper="3.14159265359" velocity="3.15"/>
    <dynamics damping="0.0" friction="0.0"/>
  </joint>
  <link name="shoulder_link">
    <visual>
      <geometry>
        <mesh filename="../meshes/ur5/visual/shoulder.dae"/>
      </geometry>
      <material name="LightGrey">
        <color rgba="0.7 0.7 0.7 1.0"/>
      </material>
    </visual>
    <collision>
      <geometry>
        <mesh filename="../meshes/ur5/collision/shoulder.stl"/>
      </geometry>
    </collision>
    <inertial>
      <mass value="3.7"/>
      <origin rpy="0 0 0" xyz="0.0 0.0 0.0"/>
      <inertia ixx="0.010267495893" ixy="0.0" ixz="0.0" iyy="0.010267495893" iyz="0.0" izz="0.00666"/>
    </inertial>
  </link>
  <joint name="shoulder_lift_joint" type="revolute">
    <parent link="shoulder_link"/>
    <child link="upper_arm_link"/>
    <origin rpy="0.0 1.57079632679 0.0" xyz="0.0 0.13585 0.0"/>
    <axis xyz="0 1 0"/>
    <limit effort="150.0" lower="-3.14159265359" upper="3.14159265359" velocity="3.15"/>
    <dynamics damping="0.0" friction="0.0"/>
  </joint>
  <link name="upper_arm_link">
    <visual>
      <geometry>
        <mesh filename="../meshes/ur5/visual/upperarm.dae"/>
      </geometry>
      <material name="LightGrey">
        <color rgba="0.7 0.7 0.7 1.0"/>
      </material>
    </visual>
    <collision>
      <geometry>
        <mesh filename="../meshes/ur5/collision/upperarm.stl"/>
      </geometry>
    </collision>
    <inertial>
      <mass value="8.393"/>
      <origin rpy="0 0 0" xyz="0.0 0.0 0.28"/>
      <inertia ixx="0.22689067591" ixy="0.0" ixz="0.0" iyy="0.22689067591" iyz="0.0" izz="0.0151074"/>
    </inertial>
  </link>
  <joint name="elbow_joint" type="revolute">
    <parent link="upper_arm_link"/>
    <child link="forearm_link"/>
    <origin rpy="0.0 0.0 0.0" xyz="0.0 -0.1197 0.425"/>
    <axis xyz="0 1 0"/>
    <limit effort="150.0" lower="-3.14159265359" upper="3.14159265359" velocity="3.15"/>
    <dynamics damping="0.0" friction="0.0"/>
  </joint>
  <link name="forearm_link">
    <visual>
      <geometry>
        <mesh filename="../meshes/ur5/visual/forearm.dae"/>
      </geometry>
      <material name="LightGrey">
        <color rgba="0.7 0.7 0.7 1.0"/>
      </material>
    </visual>
    <collision>
      <geometry>
        <mesh filename="../meshes/ur5/collision/forearm.stl"/>
      </geometry>
    </collision>
    <inertial>
      <mass value="2.275"/>
      <origin rpy="0 0 0" xyz="0.0 0.0 0.196125"/>
      <inertia ixx="0.0312167910289" ixy="0.0" ixz="0.0" iyy="0.0312167910289" iyz="0.0" izz="0.004095"/>
    </inertial>
  </link>
  <joint name="wrist_1_joint" type="revolute">
    <parent link="forearm_link"/>
    <child link="wrist_1_link"/>
    <origin rpy="0.0 1.57079632679 0.0" xyz="0.0 0.0 0.39225"/>
    <axis xyz="0 1 0"/>
    <limit effort="28.0" lower="-3.14159265359" upper="3.14159265359" velocity="3.2"/>
    <dynamics damping="0.0" friction="0.0"/>
  </joint>
  <link name="wrist_1_link">
    <visual>
      <geometry>
        <mesh filename="../meshes/ur5/visual/wrist1.dae"/>
      </geometry>
      <material name="LightGrey">
        <color rgba="0.7 0.7 0.7 1.0"/>
      </material>
    </visual>
    <collision>
      <geometry>
        <mesh filename="../meshes/ur5/collision/wrist1.stl"/>
      </geometry>
    </collision>
    <inertial>
      <mass value="1.219"/>
      <origin rpy="0 0 0" xyz="0.0 0.093 0.0"/>
      <inertia ixx="0.00255989897604" ixy="0.0" ixz="0.0" iyy="0.00255989897604" iyz="0.0" izz="0.0021942"/>
    </inertial>
  </link>
  <joint name="wrist_2_joint" type="revolute">
    <parent link="wrist_1_link"/>
    <child link="wrist_2_link"/>
    <origin rpy="0.0 0.0 0.0" xyz="0.0 0.093 0.0"/>
    <axis xyz="0 0 1"/>
    <limit effort="28.0" lower="-3.14159265359" upper="3.14159265359" velocity="3.2"/>
    <dynamics damping="0.0" friction="0.0"/>
  </joint>
  <link name="wrist_2_link">
    <visual>
      <geometry>
        <mesh filename="../meshes/ur5/visual/wrist2.dae"/>
      </geometry>
      <material name="LightGrey">
        <color rgba="0.7 0.7 0.7 1.0"/>
      </material>
    </visual>
    <collision>
      <geometry>
        <mesh filename="../meshes/ur5/collision/wrist2.stl"/>
      </geometry>
    </collision>
    <inertial>
      <mass value="1.219"/>
      <origin rpy="0 0 0" xyz="0.0 0.0 0.09465"/>
      <inertia ixx="0.00255989897604" ixy="0.0" ixz="0.0" iyy="0.00255989897604" iyz="0.0" izz="0.0021942"/>
    </inertial>
  </link>
  <joint name="wrist_3_joint" type="revolute">
    <parent link="wrist_2_link"/>
    <child link="wrist_3_link"/>
    <origin rpy="0.0 0.0 0.0" xyz="0.0 0.0 0.09465"/>
    <axis xyz="0 1 0"/>
    <limit effort="28.0" lower="-3.14159265359" upper="3.14159265359" velocity="3.2"/>
    <dynamics damping="0.0" friction="0.0"/>
  </joint>
  <link name="wrist_3_link">
    <visual>
      <geometry>
        <mesh filename="../meshes/ur5/visual/wrist3.dae"/>
      </geometry>
      <material name="LightGrey">
        <color rgba="0.7 0.7 0.7 1.0"/>
      </material>
    </visual>
    <collision>
      <geometry>
        <mesh filename="../meshes/ur5/collision/wrist3.stl"/>
      </geometry>
    </collision>
    <inertial>
      <mass value="0.1879"/>
      <origin rpy="1.57079632679 0 0" xyz="0.0 0.06505 0.0"/>
      <inertia ixx="8.46958911216e-05" ixy="0.0" ixz="0.0" iyy="8.46958911216e-05" iyz="0.0" izz="0.0001321171875"/>
    </inertial>
  </link>
  <joint name="ee_fixed_joint" type="fixed">
    <parent link="wrist_3_link"/>
    <child link="ee_link"/>
    <origin rpy="0.0 0.0 1.57079632679" xyz="0.0 0.0823 0.0"/>
  </joint>
  <link name="ee_link">
    <collision>
      <geometry>
        <box size="0.01 0.01 0.01"/>
      </geometry>
      <origin rpy="0 0 0" xyz="-0.01 0 0"/>
    </collision>
  </link>
  <transmission name="shoulder_pan_trans">
    <type>transmission_interface/SimpleTransmission</type>
    <joint name="shoulder_pan_joint">
      <hardwareInterface>hardware_interface/PositionJointInterface</hardwareInterface>
    </joint>
    <actuator name="shoulder_pan_motor">
      <mechanicalReduction>1</mechanicalReduction>
    </actuator>
  </transmission>
  <transmission name="shoulder_lift_trans">
    <type>transmission_interface/SimpleTransmission</type>
    <joint name="shoulder_lift_joint">
      <hardwareInterface>hardware_interface/PositionJointInterface</hardwareInterface>
    </joint>
    <actuator name="shoulder_lift_motor">
      <mechanicalReduction>1</mechanicalReduction>
    </actuator>
  </transmission>
  <transmission name="elbow_trans">
    <type>transmission_interface/SimpleTransmission</type>
    <joint name="elbow_joint">
      <hardwareInterface>hardware_interface/PositionJointInterface</hardwareInterface>
    </joint>
    <actuator name="elbow_motor">
      <mechanicalReduction>1</mechanicalReduction>
    </actuator>
  </transmission>
  <transmission name="wrist_1_trans">
    <type>transmission_interface/SimpleTransmission</type>
    <joint name="wrist_1_joint">
      <hardwareInterface>hardware_interface/PositionJointInterface</hardwareInterface>
    </joint>
    <actuator name="wrist_1_motor">
      <mechanicalReduction>1</mechanicalReduction>
    </actuator>
  </transmission>
  <transmission name="wrist_2_trans">
    <type>transmission_interface/SimpleTransmission</type>
    <joint name="wrist_2_joint">
      <hardwareInterface>hardware_interface/PositionJointInterface</hardwareInterface>
    </joint>
    <actuator name="wrist_2_motor">
      <mechanicalReduction>1</mechanicalReduction>
    </actuator>
  </transmission>
  <transmission name="wrist_3_trans">
    <type>transmission_interface/SimpleTransmission</type>
    <joint name="wrist_3_joint">
      <hardwareInterface>hardware_interface/PositionJointInterface</hardwareInterface>
    </joint>
    <actuator name="wrist_3_motor">
      <mechanicalReduction>1</mechanicalReduction>
    </actuator>
  </transmission>
  <gazebo reference="shoulder_link">
    <selfCollide>true</selfCollide>
  </gazebo>
  <gazebo reference="upper_arm_link">
    <selfCollide>true</selfCollide>
  </gazebo>
  <gazebo reference="forearm_link">
    <selfCollide>true</selfCollide>
  </gazebo>
  <gazebo reference="wrist_1_link">
    <selfCollide>true</selfCollide>
  </gazebo>
  <gazebo reference="wrist_3_link">
    <selfCollide>true</selfCollide>
  </gazebo>
  <gazebo reference="wrist_2_link">
    <selfCollide>true</selfCollide>
  </gazebo>
  <gazebo reference="ee_link">
    <selfCollide>true</selfCollide>
  </gazebo>
  <!-- ROS base_link to UR 'Base' Coordinates transform -->
  <link name="base"/>
  <joint name="base_link-base_fixed_joint" type="fixed">
    <!-- NOTE: this rotation is only needed as long as base_link itself is
                 not corrected wrt the real robot (ie: rotated over 180
                 degrees)
      -->
    <origin rpy="0 0 -3.14159265359" xyz="0 0 0"/>
    <parent link="base_link"/>
    <child link="base"/>
  </joint>
  <!-- Frame coincident with all-zeros TCP on UR controller -->
  <link name="tool0"/>
  <joint name="wrist_3_link-tool0_fixed_joint" type="fixed">
    <origin rpy="-1.57079632679 0 0" xyz="0 0.0823 0"/>
    <parent link="wrist_3_link"/>
    <child link="tool0"/>
  </joint>
  <joint name="ee_joint" type="fixed">
    <parent link="tool0"/>
    <child link="handbase_1"/>
    <origin rpy="0.0 0 0" xyz="0 0 0"/>
  </joint>
  <link name="handbase_1">
    <visual>
      <origin rpy="0 -0 0" xyz="-0.06 0.0545 0.00025"/>
      <geometry>
        <mesh filename="../meshes/exp_hand/pulley.stl"/>
      </geometry>
      <material name="pulley_material">
        <color rgba="0.980392 0.713725 0.00392157 1.0"/>
      </material>
    </visual>
    <collision>
      <origin rpy="0 -0 0" xyz="-0.06 0.0545 0.00025"/>
      <geometry>
        <mesh filename="../meshes/exp_hand/pulley.stl"/>
      </geometry>
      <material name="pulley_material">
        <color rgba="0.980392 0.713725 0.00392157 1.0"/>
      </material>
    </collision>
    <visual>
      <origin rpy="5.55112e-17 2.28323e-16 3.74314e-16" xyz="-0.06 0.0545 8.52833e-16"/>
      <geometry>
        <mesh filename="../meshes/exp_hand/rigidfinger.stl"/>
      </geometry>
      <material name="rigidfinger_material">
        <color rgba="0.882353 0.572549 0.478431 1.0"/>
      </material>
    </visual>
    <collision>
      <origin rpy="5.55112e-17 2.28323e-16 3.74314e-16" xyz="-0.06 0.0545 8.52833e-16"/>
      <geometry>
        <mesh filename="../meshes/exp_hand/rigidfinger.stl"/>
      </geometry>
      <material name="rigidfinger_material">
        <color rgba="0.882353 0.572549 0.478431 1.0"/>
      </material>
    </collision>
    <visual>
      <origin rpy="-0 1.5708 0" xyz="1.38778e-17 0.0545 0.029"/>
      <geometry>
        <mesh filename="../meshes/exp_hand/302534_re25_gb_20w_kl_2we.stl"/>
      </geometry>
      <material name="302534_re25_gb_20w_kl_2we_material">
        <color rgba="0.917647 0.917647 0.917647 1.0"/>
      </material>
    </visual>
    <collision>
      <origin rpy="-0 1.5708 0" xyz="1.38778e-17 0.0545 0.029"/>
      <geometry>
        <mesh filename="../meshes/exp_hand/302534_re25_gb_20w_kl_2we.stl"/>
      </geometry>
      <material name="302534_re25_gb_20w_kl_2we_material">
        <color rgba="0.917647 0.917647 0.917647 1.0"/>
      </material>
    </collision>
    <visual>
      <origin rpy="0 -0 0" xyz="-0.06 0.0545 0.00025"/>
      <geometry>
        <mesh filename="../meshes/exp_hand/pulley.stl"/>
      </geometry>
      <material name="pulley_material">
        <color rgba="0.980392 0.713725 0.00392157 1.0"/>
      </material>
    </visual>
    <collision>
      <origin rpy="0 -0 0" xyz="-0.06 0.0545 0.00025"/>
      <geometry>
        <mesh filename="../meshes/exp_hand/pulley.stl"/>
      </geometry>
      <material name="pulley_material">
        <color rgba="0.980392 0.713725 0.00392157 1.0"/>
      </material>
    </collision>
    <visual>
      <origin rpy="0 -0 0" xyz="-0.06 0.0545 -0.0149582"/>
      <geometry>
        <mesh filename="../meshes/exp_hand/dowel-m3-l24.stl"/>
      </geometry>
      <material name="dowel-m3-l24_material">
        <color rgba="0.752941 0.752941 0.752941 1.0"/>
      </material>
    </visual>
    <collision>
      <origin rpy="0 -0 0" xyz="-0.06 0.0545 -0.0149582"/>
      <geometry>
        <mesh filename="../meshes/exp_hand/dowel-m3-l24.stl"/>
      </geometry>
      <material name="dowel-m3-l24_material">
        <color rgba="0.752941 0.752941 0.752941 1.0"/>
      </material>
    </collision>
    <visual>
      <origin rpy="2.02111e-26 9.52613e-17 9.63735e-17" xyz="-0.06 0.0545 6.07153e-18"/>
      <geometry>
        <mesh filename="../meshes/exp_hand/handbase.stl"/>
      </geometry>
      <material name="handbase_material">
        <color rgba="0.529412 0.568627 0.6 1.0"/>
      </material>
    </visual>
    <collision>
      <origin rpy="2.02111e-26 9.52613e-17 9.63735e-17" xyz="-0.06 0.0545 6.07153e-18"/>
      <geometry>
        <mesh filename="../meshes/exp_hand/handbase.stl"/>
      </geometry>
      <material name="handbase_material">
        <color rgba="0.529412 0.568627 0.6 1.0"/>
      </material>
    </collision>
    <visual>
      <origin rpy="1.0413e-28 -0 2.34901e-31" xyz="-0.06 0.0545 -1.38778e-17"/>
      <geometry>
        <mesh filename="../meshes/exp_hand/linearrail120.stl"/>
      </geometry>
      <material name="linearrail120_material">
        <color rgba="0.752941 0.752941 0.752941 1.0"/>
      </material>
    </visual>
    <collision>
      <origin rpy="1.0413e-28 -0 2.34901e-31" xyz="-0.06 0.0545 -1.38778e-17"/>
      <geometry>
        <mesh filename="../meshes/exp_hand/linearrail120.stl"/>
      </geometry>
      <material name="linearrail120_material">
        <color rgba="0.752941 0.752941 0.752941 1.0"/>
      </material>
    </collision>
    <visual>
      <origin rpy="1.5708 5.55112e-17 -1.5708" xyz="-0.039 0.0365 0.14375"/>
      <geometry>
        <mesh filename="../meshes/exp_hand/c-203-pad_distal_blank.stl"/>
      </geometry>
      <material name="c-203-pad_distal_blank_material">
        <color rgba="0.615686 0.811765 0.929412 1.0"/>
      </material>
    </visual>
    <collision>
      <origin rpy="1.5708 5.55112e-17 -1.5708" xyz="-0.039 0.0365 0.14375"/>
      <geometry>
        <mesh filename="../meshes/exp_hand/c-203-pad_distal_blank.stl"/>
      </geometry>
      <material name="c-203-pad_distal_blank_material">
        <color rgba="0.615686 0.811765 0.929412 1.0"/>
      </material>
    </collision>
    <visual>
      <origin rpy="-3.14159 1.5708 0" xyz="-0.0575 0.052 0.072"/>
      <geometry>
        <mesh filename="../meshes/exp_hand/dowelm3-32.stl"/>
      </geometry>
      <material name="dowelm3-32_material">
        <color rgba="0.752941 0.752941 0.752941 1.0"/>
      </material>
    </visual>
    <collision>
      <origin rpy="-3.14159 1.5708 0" xyz="-0.0575 0.052 0.072"/>
      <geometry>
        <mesh filename="../meshes/exp_hand/dowelm3-32.stl"/>
      </geometry>
      <material name="dowelm3-32_material">
        <color rgba="0.752941 0.752941 0.752941 1.0"/>
      </material>
    </collision>
    <visual>
      <origin rpy="3.14159 -0 0" xyz="-0.051 0.05125 0.0684125"/>
      <geometry>
        <mesh filename="../meshes/exp_hand/neodyniummagnets.stl"/>
      </geometry>
      <material name="neodyniummagnets_material">
        <color rgba="0.752941 0.752941 0.752941 1.0"/>
      </material>
    </visual>
    <collision>
      <origin rpy="3.14159 -0 0" xyz="-0.051 0.05125 0.0684125"/>
      <geometry>
        <mesh filename="../meshes/exp_hand/neodyniummagnets.stl"/>
      </geometry>
      <material name="neodyniummagnets_material">
        <color rgba="0.752941 0.752941 0.752941 1.0"/>
      </material>
    </collision>
    <visual>
      <origin rpy="6.93889e-18 -2.16037e-16 1.03961e-15" xyz="-0.051 0.05125 0.0725875"/>
      <geometry>
        <mesh filename="../meshes/exp_hand/neodyniummagnets.stl"/>
      </geometry>
      <material name="neodyniummagnets_material">
        <color rgba="0.752941 0.752941 0.752941 1.0"/>
      </material>
    </visual>
    <collision>
      <origin rpy="6.93889e-18 -2.16037e-16 1.03961e-15" xyz="-0.051 0.05125 0.0725875"/>
      <geometry>
        <mesh filename="../meshes/exp_hand/neodyniummagnets.stl"/>
      </geometry>
      <material name="neodyniummagnets_material">
        <color rgba="0.752941 0.752941 0.752941 1.0"/>
      </material>
    </collision>
    <visual>
      <origin rpy="0 -0 0" xyz="-0.06 0.0545 -0.0149582"/>
      <geometry>
        <mesh filename="../meshes/exp_hand/dowel-m3-l24.stl"/>
      </geometry>
      <material name="dowel-m3-l24_material">
        <color rgba="0.752941 0.752941 0.752941 1.0"/>
      </material>
    </visual>
    <collision>
      <origin rpy="0 -0 0" xyz="-0.06 0.0545 -0.0149582"/>
      <geometry>
        <mesh filename="../meshes/exp_hand/dowel-m3-l24.stl"/>
      </geometry>
      <material name="dowel-m3-l24_material">
        <color rgba="0.752941 0.752941 0.752941 1.0"/>
      </material>
    </collision>
    <visual>
      <origin rpy="-3.14159 1.68053e-18 9.63735e-17" xyz="-0.0428275 0.0155 0.067"/>
      <geometry>
        <mesh filename="../meshes/exp_hand/dowel-m3-l24.stl"/>
      </geometry>
      <material name="dowel-m3-l24_material">
        <color rgba="0.752941 0.752941 0.752941 1.0"/>
      </material>
    </visual>
    <collision>
      <origin rpy="-3.14159 1.68053e-18 9.63735e-17" xyz="-0.0428275 0.0155 0.067"/>
      <geometry>
        <mesh filename="../meshes/exp_hand/dowel-m3-l24.stl"/>
      </geometry>
      <material name="dowel-m3-l24_material">
        <color rgba="0.752941 0.752941 0.752941 1.0"/>
      </material>
    </collision>
    <visual>
      <origin rpy="0 -0 0" xyz="-0.06 0.0545 0"/>
      <geometry>
        <mesh filename="../meshes/exp_hand/motormountplate.stl"/>
      </geometry>
      <material name="motormountplate_material">
        <color rgba="0.917647 0.72549 0.490196 1.0"/>
      </material>
    </visual>
    <collision>
      <origin rpy="0 -0 0" xyz="-0.06 0.0545 0"/>
      <geometry>
        <mesh filename="../meshes/exp_hand/motormountplate.stl"/>
      </geometry>
      <material name="motormountplate_material">
        <color rgba="0.917647 0.72549 0.490196 1.0"/>
      </material>
    </collision>
    <visual>
      <origin rpy="0 -0 0" xyz="1.38778e-17 0.0545 0.0349"/>
      <geometry>
        <mesh filename="../meshes/exp_hand/capstan20mm.stl"/>
      </geometry>
      <material name="capstan20mm_material">
        <color rgba="0.972549 0.529412 0.00392157 1.0"/>
      </material>
    </visual>
    <collision>
      <origin rpy="0 -0 0" xyz="1.38778e-17 0.0545 0.0349"/>
      <geometry>
        <mesh filename="../meshes/exp_hand/capstan20mm.stl"/>
      </geometry>
      <material name="capstan20mm_material">
        <color rgba="0.972549 0.529412 0.00392157 1.0"/>
      </material>
    </collision>
    <visual>
      <origin rpy="-3.14159 1.5708 0" xyz="-0.0575 0.021 0.072"/>
      <geometry>
        <mesh filename="../meshes/exp_hand/dowelm3-32.stl"/>
      </geometry>
      <material name="dowelm3-32_material">
        <color rgba="0.752941 0.752941 0.752941 1.0"/>
      </material>
    </visual>
    <collision>
      <origin rpy="-3.14159 1.5708 0" xyz="-0.0575 0.021 0.072"/>
      <geometry>
        <mesh filename="../meshes/exp_hand/dowelm3-32.stl"/>
      </geometry>
      <material name="dowelm3-32_material">
        <color rgba="0.752941 0.752941 0.752941 1.0"/>
      </material>
    </collision>
    <inertial>
      <origin rpy="0 0 0" xyz="-0.0152113 0.0472565 0.0515526"/>
      <mass value="0.24021"/>
      <inertia ixx="0.000752849" ixy="-4.05009e-05" ixz="0.000254613" iyy="0.000884835" iyz="0.000105384" izz="0.000193105"/>
    </inertial>
  </link>
  <link name="softfinger_1">
    <visual>
      <origin rpy="4.16041e-30 -0 0" xyz="-0.0095 -0.0011 -0.00175"/>
      <geometry>
        <mesh filename="../meshes/exp_hand/carriage_ml5c1s1.stl"/>
      </geometry>
      <material name="carriage_ml5c1s1_material">
        <color rgba="0.752941 0.752941 0.752941 1.0"/>
      </material>
    </visual>
    <collision>
      <origin rpy="4.16041e-30 -0 0" xyz="-0.0095 -0.0011 -0.00175"/>
      <geometry>
        <mesh filename="../meshes/exp_hand/carriage_ml5c1s1.stl"/>
      </geometry>
      <material name="carriage_ml5c1s1_material">
        <color rgba="0.752941 0.752941 0.752941 1.0"/>
      </material>
    </collision>
    <visual>
      <origin rpy="-1.5708 3.26639e-30 -1.5708" xyz="0.003 -0.03058 0.00305"/>
      <geometry>
        <mesh filename="../meshes/exp_hand/brassinsert.stl"/>
      </geometry>
      <material name="brassinsert_material">
        <color rgba="0.756863 0.462745 0.109804 1.0"/>
      </material>
    </visual>
    <collision>
      <origin rpy="-1.5708 3.26639e-30 -1.5708" xyz="0.003 -0.03058 0.00305"/>
      <geometry>
        <mesh filename="../meshes/exp_hand/brassinsert.stl"/>
      </geometry>
      <material name="brassinsert_material">
        <color rgba="0.756863 0.462745 0.109804 1.0"/>
      </material>
    </collision>
    <visual>
      <origin rpy="1.5708 1.5708 0" xyz="-0.0017752 -0.03058 0.00305"/>
      <geometry>
        <mesh filename="../meshes/exp_hand/ventedscrewlong.stl"/>
      </geometry>
      <material name="ventedscrewlong_material">
        <color rgba="0.752941 0.752941 0.752941 1.0"/>
      </material>
    </visual>
    <collision>
      <origin rpy="1.5708 1.5708 0" xyz="-0.0017752 -0.03058 0.00305"/>
      <geometry>
        <mesh filename="../meshes/exp_hand/ventedscrewlong.stl"/>
      </geometry>
      <material name="ventedscrewlong_material">
        <color rgba="0.752941 0.752941 0.752941 1.0"/>
      </material>
    </collision>
    <visual>
      <origin rpy="7.44686e-15 1.5708 0" xyz="-0.004 0.07145 -0.00175"/>
      <geometry>
        <mesh filename="../meshes/exp_hand/c-203-pad_distal_blank.stl"/>
      </geometry>
      <material name="c-203-pad_distal_blank_material">
        <color rgba="0.615686 0.811765 0.929412 1.0"/>
      </material>
    </visual>
    <collision>
      <origin rpy="7.44686e-15 1.5708 0" xyz="-0.004 0.07145 -0.00175"/>
      <geometry>
        <mesh filename="../meshes/exp_hand/c-203-pad_distal_blank.stl"/>
      </geometry>
      <material name="c-203-pad_distal_blank_material">
        <color rgba="0.615686 0.811765 0.929412 1.0"/>
      </material>
    </collision>
    <visual>
      <origin rpy="-1.5708 6.83944e-15 -7.63056e-15" xyz="0.002 0.0087 -0.00175"/>
      <geometry>
        <mesh filename="../meshes/exp_hand/mobilefinger.stl"/>
      </geometry>
      <material name="mobilefinger_material">
        <color rgba="0.980392 0.713725 0.00392157 1.0"/>
      </material>
    </visual>
    <collision>
      <origin rpy="-1.5708 6.83944e-15 -7.63056e-15" xyz="0.002 0.0087 -0.00175"/>
      <geometry>
        <mesh filename="../meshes/exp_hand/mobilefinger.stl"/>
      </geometry>
      <material name="mobilefinger_material">
        <color rgba="0.980392 0.713725 0.00392157 1.0"/>
      </material>
    </collision>
    <inertial>
      <origin rpy="0 0 0" xyz="0.00228341 0.0480489 -0.00151808"/>
      <mass value="0.0747607"/>
      <inertia ixx="7.4277e-05" ixy="5.77742e-06" ixz="-1.60791e-07" iyy="5.52364e-06" iyz="1.19371e-06" izz="7.28249e-05"/>
    </inertial>
  </link>
  <joint name="main" type="prismatic">
    <origin rpy="1.5708 -0 0" xyz="0.0370066 0.03475 0.0723"/>
    <parent link="handbase_1"/>
    <child link="softfinger_1"/>
    <axis xyz="-1 0 0"/>
    <limit effort="100" velocity="20"/>
    <joint_properties friction="0.0"/>
  </joint>
  <!-- define the ur5's position and orientation in the world coordinate system -->
  <link name="world"/>
  <joint name="world_joint" type="fixed">
    <parent link="world"/>
    <child link="base_link"/>
    <origin rpy="0.0 0.0 0.0" xyz="0.0 0.0 0.0"/>
  </joint>
  <transmission name="tran1">
    <type>transmission_interface/SimpleTransmission</type>
    <joint name="linear">
      <hardwareInterface>hardware_interface/EffortJointInterface</hardwareInterface>
    </joint>
    <actuator name="motor1">
      <hardwareInterface>hardware_interface/EffortJointInterface</hardwareInterface>
      <mechanicalReduction>1</mechanicalReduction>
    </actuator>
  </transmission>
</robot>
